<?xml version="1.0" ?>
<!-- Generated using onshape-to-robot -->
<!-- Onshape https://cad.onshape.com/documents/247f053335409b137ca0a3fa/w/ba9bac7773eb7e8311a3657d/e/53a5758d6eaac2842871f233 -->
<robot name="my-robot" xmlns:xacro="http://www.ros.org/wiki/xacro">

  <xacro:include filename="$(find full_robot)/urdf/manipulator.xacro"/>
  
  <link name="base">
    <inertial>
      <origin xyz="7.15175e-09 0.00387039 0.176709" rpy="0 0 0"/>
      <mass value="14.1165"/>
      <inertia ixx="0.712488" ixy="-3.32307e-08" ixz="2.04252e-08" iyy="0.743813" iyz="0.0147188" izz="0.588331"/>
    </inertial>
  </link>
  <link name="imu_link">
    <visual>
      <origin xyz="0 0 0" rpy="0 0 0"/>
      <geometry>
        <mesh filename="file://$(find full_robot)/assets/imu.stl"/>
      </geometry>
      <material name="imu_material">
        <color rgba="0 0 1 1"/>
      </material>
    </visual>
    <collision>
      <origin xyz="0 0 0" rpy="0 0 0"/>
      <geometry>
        <mesh filename="file://$(find full_robot)/assets/imu.stl"/>
      </geometry>
    </collision>
  </link>
  <joint name="base_to_imu" type="fixed">
    <parent link="base"/>
    <child link="imu_link"/>
    <origin xyz="-2.36447e-17 -5.80614e-17 0.083" rpy="0 0 6.12323e-17"/>
  </joint>
  <link name="lidar_link">
    <visual>
      <origin xyz="0 0 0" rpy="0 0 0"/>
      <geometry>
        <mesh filename="file://$(find full_robot)/assets/lidar.stl"/>
      </geometry>
      <material name="lidar_material">
        <color rgba="0.6 0.6 0.6 1"/>
      </material>
    </visual>
    <collision>
      <origin xyz="0 0 0" rpy="0 0 0"/>
      <geometry>
        <mesh filename="file://$(find full_robot)/assets/lidar.stl"/>
      </geometry>
    </collision>
  </link>
  <joint name="base_to_lidar" type="fixed">
    <parent link="base"/>
    <child link="lidar_link"/>
    <origin xyz="-2.24826e-17 -6.22208e-17 0.092" rpy="0 0 6.12323e-17"/>
  </joint>
  <link name="motor_link">
    <visual>
      <origin xyz="0 0 0" rpy="0 0 0"/>
      <geometry>
        <mesh filename="file://$(find full_robot)/assets/motor.stl"/>
      </geometry>
      <material name="motor_material">
        <color rgba="0.756863 0.67451 0.580392 1"/>
      </material>
    </visual>
    <collision>
      <origin xyz="0 0 0" rpy="0 0 0"/>
      <geometry>
        <mesh filename="file://$(find full_robot)/assets/motor.stl"/>
      </geometry>
    </collision>
  </link>
  <joint name="base_to_motor" type="fixed">
    <parent link="base"/>
    <child link="motor_link"/>
    <origin xyz="0 0.155075 -0.04535" rpy="0 0 -3.14159"/>
  </joint>
  <link name="mdf_motores_link">
    <visual>
      <origin xyz="0 0 0" rpy="0 0 0"/>
      <geometry>
        <mesh filename="file://$(find full_robot)/assets/mdf_motores.stl"/>
      </geometry>
      <material name="mdf_motores_material">
        <color rgba="0.84 0.78 0.63 1.0"/>
      </material>
    </visual>
    <collision>
      <origin xyz="0 0 0" rpy="0 0 0"/>
      <geometry>
        <mesh filename="file://$(find full_robot)/assets/mdf_motores.stl"/>
      </geometry>
    </collision>
  </link>
  <joint name="base_to_mdf_motores" type="fixed">
    <parent link="base"/>
    <child link="mdf_motores_link"/>
    <origin xyz="0 0 0" rpy="0 0 -1.5708"/>
  </joint>
  <link name="mdf_tampa_link">
    <visual>
      <origin xyz="0 0 0" rpy="0 0 0"/>
      <geometry>
        <mesh filename="file://$(find full_robot)/assets/mdf_tampa.stl"/>
      </geometry>
      <material name="mdf_tampa_material">
        <color rgba="0.84 0.78 0.63 1.0"/>
      </material>
    </visual>
    <collision>
      <origin xyz="0 0 0" rpy="0 0 0"/>
      <geometry>
        <mesh filename="file://$(find full_robot)/assets/mdf_tampa.stl"/>
      </geometry>
    </collision>
  </link>
  <joint name="base_to_mdf_tampa" type="fixed">
    <parent link="base"/>
    <child link="mdf_tampa_link"/>
    <origin xyz="-1.54582e-17 -4.16334e-17 0.4975" rpy="0 0 -1.5708"/>
  </joint>
  <link name="capa_baixo_link">
    <visual>
      <origin xyz="0 0 0" rpy="0 0 0"/>
      <geometry>
        <mesh filename="file://$(find full_robot)/assets/capa_baixo.stl"/>
      </geometry>
      <material name="capa_baixo_material">
        <color rgba="0.901961 0.901961 0.901961 1"/>
      </material>
    </visual>
    <collision>
      <origin xyz="0 0 0" rpy="0 0 0"/>
      <geometry>
        <mesh filename="file://$(find full_robot)/assets/capa_baixo.stl"/>
      </geometry>
    </collision>
  </link>
  <joint name="base_to_capa_baixo" type="fixed">
    <parent link="base"/>
    <child link="capa_baixo_link"/>
    <origin xyz="6.93889e-18 -4.16334e-17 -0.078" rpy="0 0 0"/>
  </joint>
  <link name="mdf_link">
    <visual>
      <origin xyz="0 0 0" rpy="0 0 0"/>
      <geometry>
        <mesh filename="file://$(find full_robot)/assets/mdf.stl"/>
      </geometry>
      <material name="mdf_material">
        <color rgba="0.84 0.78 0.63 1.0"/>
      </material>
    </visual>
    <collision>
      <origin xyz="0 0 0" rpy="0 0 0"/>
      <geometry>
        <mesh filename="file://$(find full_robot)/assets/mdf.stl"/>
      </geometry>
    </collision>
  </link>
  <joint name="base_to_mdf" type="fixed">
    <parent link="base"/>
    <child link="mdf_link"/>
    <origin xyz="1.54074e-33 -1.38778e-17 0.086" rpy="0 0 -1.5708"/>
  </joint>
  <link name="mdf_2_link">
    <visual>
      <origin xyz="0 0 0" rpy="0 0 0"/>
      <geometry>
        <mesh filename="file://$(find full_robot)/assets/mdf.stl"/>
      </geometry>
      <material name="mdf_2_material">
        <color rgba="0.84 0.78 0.63 1.0"/>
      </material>
    </visual>
    <collision>
      <origin xyz="0 0 0" rpy="0 0 0"/>
      <geometry>
        <mesh filename="file://$(find full_robot)/assets/mdf.stl"/>
      </geometry>
    </collision>
  </link>
  <joint name="base_to_mdf_2" type="fixed">
    <parent link="base"/>
    <child link="mdf_2_link"/>
    <origin xyz="1.54074e-33 -1.38778e-17 0.132" rpy="0 0 -1.5708"/>
  </joint>
  <link name="led_link">
    <visual>
      <origin xyz="0 0 0" rpy="0 0 0"/>
      <geometry>
        <mesh filename="file://$(find full_robot)/assets/led.stl"/>
      </geometry>
      <material name="led_material">
        <color rgba="1 1 1 1"/>
      </material>
    </visual>
    <collision>
      <origin xyz="0 0 0" rpy="0 0 0"/>
      <geometry>
        <mesh filename="file://$(find full_robot)/assets/led.stl"/>
      </geometry>
    </collision>
  </link>
  <joint name="base_to_led" type="fixed">
    <parent link="base"/>
    <child link="led_link"/>
    <origin xyz="6.93889e-18 -4.16334e-17 0.142" rpy="0 0 0"/>
  </joint>
  <link name="perfil_motores_link">
    <visual>
      <origin xyz="0 0 0" rpy="0 0 0"/>
      <geometry>
        <mesh filename="file://$(find full_robot)/assets/perfil_motores.stl"/>
      </geometry>
      <material name="perfil_motores_material">
        <color rgba="0.901961 0.901961 0.901961 1"/>
      </material>
    </visual>
    <collision>
      <origin xyz="0 0 0" rpy="0 0 0"/>
      <geometry>
        <mesh filename="file://$(find full_robot)/assets/perfil_motores.stl"/>
      </geometry>
    </collision>
  </link>
  <joint name="base_to_perfil_motores" type="fixed">
    <parent link="base"/>
    <child link="perfil_motores_link"/>
    <origin xyz="0 0.207375 -0.01" rpy="0 0 -3.14159"/>
  </joint>
  <link name="capa_cima_link">
    <visual>
      <origin xyz="0 0 0" rpy="0 0 0"/>
      <geometry>
        <mesh filename="file://$(find full_robot)/assets/capa_cima.stl"/>
      </geometry>
      <material name="capa_cima_material">
        <color rgba="0.901961 0.901961 0.901961 1"/>
      </material>
    </visual>
    <collision>
      <origin xyz="0 0 0" rpy="0 0 0"/>
      <geometry>
        <mesh filename="file://$(find full_robot)/assets/capa_cima.stl"/>
      </geometry>
    </collision>
  </link>
  <joint name="base_to_capa_cima" type="fixed">
    <parent link="base"/>
    <child link="capa_cima_link"/>
    <origin xyz="6.93889e-18 -4.16334e-17 0.142" rpy="0 0 0"/>
  </joint>
  <link name="perfil_coluna_link">
    <visual>
      <origin xyz="0 0 0" rpy="0 0 0"/>
      <geometry>
        <mesh filename="file://$(find full_robot)/assets/perfil_coluna.stl"/>
      </geometry>
      <material name="perfil_coluna_material">
        <color rgba="0.901961 0.901961 0.901961 1"/>
      </material>
    </visual>
    <collision>
      <origin xyz="0 0 0" rpy="0 0 0"/>
      <geometry>
        <mesh filename="file://$(find full_robot)/assets/perfil_coluna.stl"/>
      </geometry>
    </collision>
  </link>
  <joint name="base_to_perfil_coluna" type="fixed">
    <parent link="base"/>
    <child link="perfil_coluna_link"/>
    <origin xyz="1.92083e-17 0.200375 0.107" rpy="0 0 0"/>
  </joint>
  <link name="perfil_motores_2_link">
    <visual>
      <origin xyz="0 0 0" rpy="0 0 0"/>
      <geometry>
        <mesh filename="file://$(find full_robot)/assets/perfil_motores.stl"/>
      </geometry>
      <material name="perfil_motores_2_material">
        <color rgba="0.901961 0.901961 0.901961 1"/>
      </material>
    </visual>
    <collision>
      <origin xyz="0 0 0" rpy="0 0 0"/>
      <geometry>
        <mesh filename="file://$(find full_robot)/assets/perfil_motores.stl"/>
      </geometry>
    </collision>
  </link>
  <joint name="base_to_perfil_motores_2" type="fixed">
    <parent link="base"/>
    <child link="perfil_motores_2_link"/>
    <origin xyz="-0.179592 -0.103688 -0.01" rpy="0 0 -1.0472"/>
  </joint>
  <link name="mdf_3_link">
    <visual>
      <origin xyz="0 0 0" rpy="0 0 0"/>
      <geometry>
        <mesh filename="file://$(find full_robot)/assets/mdf.stl"/>
      </geometry>
      <material name="mdf_3_material">
        <color rgba="0.84 0.78 0.63 1.0"/>
      </material>
    </visual>
    <collision>
      <origin xyz="0 0 0" rpy="0 0 0"/>
      <geometry>
        <mesh filename="file://$(find full_robot)/assets/mdf.stl"/>
      </geometry>
    </collision>
  </link>
  <joint name="base_to_mdf_3" type="fixed">
    <parent link="base"/>
    <child link="mdf_3_link"/>
    <origin xyz="1.54074e-33 -1.38778e-17 0.208" rpy="0 0 -1.5708"/>
  </joint>
  <link name="motor_2_link">
    <visual>
      <origin xyz="0 0 0" rpy="0 0 0"/>
      <geometry>
        <mesh filename="file://$(find full_robot)/assets/motor.stl"/>
      </geometry>
      <material name="motor_2_material">
        <color rgba="0.756863 0.67451 0.580392 1"/>
      </material>
    </visual>
    <collision>
      <origin xyz="0 0 0" rpy="0 0 0"/>
      <geometry>
        <mesh filename="file://$(find full_robot)/assets/motor.stl"/>
      </geometry>
    </collision>
  </link>
  <joint name="base_to_motor_2" type="fixed">
    <parent link="base"/>
    <child link="motor_2_link"/>
    <origin xyz="0.134299 -0.0775375 -0.04535" rpy="0 0 1.0472"/>
  </joint>
  <link name="motor_3_link">
    <visual>
      <origin xyz="0 0 0" rpy="0 0 0"/>
      <geometry>
        <mesh filename="file://$(find full_robot)/assets/motor.stl"/>
      </geometry>
      <material name="motor_3_material">
        <color rgba="0.756863 0.67451 0.580392 1"/>
      </material>
    </visual>
    <collision>
      <origin xyz="0 0 0" rpy="0 0 0"/>
      <geometry>
        <mesh filename="file://$(find full_robot)/assets/motor.stl"/>
      </geometry>
    </collision>
  </link>
  <joint name="base_to_motor_3" type="fixed">
    <parent link="base"/>
    <child link="motor_3_link"/>
    <origin xyz="-0.134299 -0.0775375 -0.04535" rpy="0 0 -1.0472"/>
  </joint>
  <link name="perfil_coluna_2_link">
    <visual>
      <origin xyz="0 0 0" rpy="0 0 0"/>
      <geometry>
        <mesh filename="file://$(find full_robot)/assets/perfil_coluna__2.stl"/>
      </geometry>
      <material name="perfil_coluna_2_material">
        <color rgba="0.901961 0.901961 0.901961 1"/>
      </material>
    </visual>
    <collision>
      <origin xyz="0 0 0" rpy="0 0 0"/>
      <geometry>
        <mesh filename="file://$(find full_robot)/assets/perfil_coluna__2.stl"/>
      </geometry>
    </collision>
  </link>
  <joint name="base_to_perfil_coluna_2" type="fixed">
    <parent link="base"/>
    <child link="perfil_coluna_2_link"/>
    <origin xyz="0.17353 -0.100188 0.25175" rpy="0 0 1.0472"/>
  </joint>
  <link name="perfil_coluna_3_link">
    <visual>
      <origin xyz="0 0 0" rpy="0 0 0"/>
      <geometry>
        <mesh filename="file://$(find full_robot)/assets/perfil_coluna__2.stl"/>
      </geometry>
      <material name="perfil_coluna_3_material">
        <color rgba="0.901961 0.901961 0.901961 1"/>
      </material>
    </visual>
    <collision>
      <origin xyz="0 0 0" rpy="0 0 0"/>
      <geometry>
        <mesh filename="file://$(find full_robot)/assets/perfil_coluna__2.stl"/>
      </geometry>
    </collision>
  </link>
  <joint name="base_to_perfil_coluna_3" type="fixed">
    <parent link="base"/>
    <child link="perfil_coluna_3_link"/>
    <origin xyz="-0.17353 -0.100188 0.25175" rpy="0 0 -1.0472"/>
  </joint>
  <link name="perfil_motores_3_link">
    <visual>
      <origin xyz="0 0 0" rpy="0 0 0"/>
      <geometry>
        <mesh filename="file://$(find full_robot)/assets/perfil_motores.stl"/>
      </geometry>
      <material name="perfil_motores_3_material">
        <color rgba="0.901961 0.901961 0.901961 1"/>
      </material>
    </visual>
    <collision>
      <origin xyz="0 0 0" rpy="0 0 0"/>
      <geometry>
        <mesh filename="file://$(find full_robot)/assets/perfil_motores.stl"/>
      </geometry>
    </collision>
  </link>
  <joint name="base_to_perfil_motores_3" type="fixed">
    <parent link="base"/>
    <child link="perfil_motores_3_link"/>
    <origin xyz="0.179592 -0.103688 -0.01" rpy="0 0 1.0472"/>
  </joint>
  <link name="perfil_coluna_carga_link">
    <visual>
      <origin xyz="0 0 0" rpy="0 0 0"/>
      <geometry>
        <mesh filename="file://$(find full_robot)/assets/perfil_coluna_carga.stl"/>
      </geometry>
      <material name="perfil_coluna_carga_material">
        <color rgba="0.901961 0.901961 0.901961 1"/>
      </material>
    </visual>
    <collision>
      <origin xyz="0 0 0" rpy="0 0 0"/>
      <geometry>
        <mesh filename="file://$(find full_robot)/assets/perfil_coluna_carga.stl"/>
      </geometry>
    </collision>
  </link>
  <joint name="base_to_perfil_coluna_carga" type="fixed">
    <parent link="base"/>
    <child link="perfil_coluna_carga_link"/>
    <origin xyz="5.01335e-14 4.25077e-14 0.214" rpy="0 0 -3.14159"/>
  </joint>
  <link name="capa_carga_link">
    <visual>
      <origin xyz="0 0 0" rpy="0 0 0"/>
      <geometry>
        <mesh filename="file://$(find full_robot)/assets/capa_carga.stl"/>
      </geometry>
      <material name="capa_carga_material">
        <color rgba="0.901961 0.901961 0.901961 1"/>
      </material>
    </visual>
    <collision>
      <origin xyz="0 0 0" rpy="0 0 0"/>
      <geometry>
        <mesh filename="file://$(find full_robot)/assets/capa_carga.stl"/>
      </geometry>
    </collision>
  </link>
  <joint name="base_to_capa_carga" type="fixed">
    <parent link="base"/>
    <child link="capa_carga_link"/>
    <origin xyz="6.245e-17 9.71445e-17 0.214" rpy="0 0 -1.5708"/>
  </joint>
  <link name="perfil_coluna_carga_2_link">
    <visual>
      <origin xyz="0 0 0" rpy="0 0 0"/>
      <geometry>
        <mesh filename="file://$(find full_robot)/assets/perfil_coluna_carga.stl"/>
      </geometry>
      <material name="perfil_coluna_carga_2_material">
        <color rgba="0.901961 0.901961 0.901961 1"/>
      </material>
    </visual>
    <collision>
      <origin xyz="0 0 0" rpy="0 0 0"/>
      <geometry>
        <mesh filename="file://$(find full_robot)/assets/perfil_coluna_carga.stl"/>
      </geometry>
    </collision>
  </link>
  <joint name="base_to_perfil_coluna_carga_2" type="fixed">
    <parent link="base"/>
    <child link="perfil_coluna_carga_2_link"/>
    <origin xyz="6.245e-17 9.71445e-17 0.214" rpy="0 0 -1.5708"/>
  </joint>
  <link name="perfil_coluna_carga_3_link">
    <visual>
      <origin xyz="0 0 0" rpy="0 0 0"/>
      <geometry>
        <mesh filename="file://$(find full_robot)/assets/perfil_coluna_carga.stl"/>
      </geometry>
      <material name="perfil_coluna_carga_3_material">
        <color rgba="0.901961 0.901961 0.901961 1"/>
      </material>
    </visual>
    <collision>
      <origin xyz="0 0 0" rpy="0 0 0"/>
      <geometry>
        <mesh filename="file://$(find full_robot)/assets/perfil_coluna_carga.stl"/>
      </geometry>
    </collision>
  </link>
  <joint name="base_to_perfil_coluna_carga_3" type="fixed">
    <parent link="base"/>
    <child link="perfil_coluna_carga_3_link"/>
    <origin xyz="0.48 -7.1487e-15 0.214" rpy="0 0 -1.5708"/>
  </joint>
  <link name="mdf_carga_link">
    <visual>
      <origin xyz="0 0 0" rpy="0 0 0"/>
      <geometry>
        <mesh filename="file://$(find full_robot)/assets/mdf_carga.stl"/>
      </geometry>
      <material name="mdf_carga_material">
        <color rgba="0.84 0.78 0.63 1.0"/>
      </material>
    </visual>
    <collision>
      <origin xyz="0 0 0" rpy="0 0 0"/>
      <geometry>
        <mesh filename="file://$(find full_robot)/assets/mdf_carga.stl"/>
      </geometry>
    </collision>
  </link>
  <joint name="base_to_mdf_carga" type="fixed">
    <parent link="base"/>
    <child link="mdf_carga_link"/>
    <origin xyz="6.245e-17 9.71445e-17 0.4975" rpy="0 0 -1.5708"/>
  </joint>
  <link name="mdf_carga_2_link">
    <visual>
      <origin xyz="0 0 0" rpy="0 0 0"/>
      <geometry>
        <mesh filename="file://$(find full_robot)/assets/mdf_carga.stl"/>
      </geometry>
      <material name="mdf_carga_2_material">
        <color rgba="0.84 0.78 0.63 1.0"/>
      </material>
    </visual>
    <collision>
      <origin xyz="0 0 0" rpy="0 0 0"/>
      <geometry>
        <mesh filename="file://$(find full_robot)/assets/mdf_carga.stl"/>
      </geometry>
    </collision>
  </link>
  <joint name="base_to_mdf_carga_2" type="fixed">
    <parent link="base"/>
    <child link="mdf_carga_2_link"/>
    <origin xyz="6.245e-17 9.71445e-17 0.214" rpy="0 0 -1.5708"/>
  </joint>

    <!-- Link roda -->
  <link name="roda">
    <inertial>
      <origin xyz="2.51575e-17 -5.10809e-18 -0.0362488" rpy="0 0 0"/>
      <mass value="0.174179"/>
      <inertia ixx="0.000112667" ixy="0" ixz="1.92475e-20" iyy="0.000112667" iyz="0" izz="0.000186298"/>
    </inertial>
    <!-- Part roda -->
    <visual>
      <origin xyz="2.2562e-17 0 -0.038" rpy="1.5708 -6.58658e-17 0"/>
      <geometry>
        <mesh filename="file://$(find full_robot)/assets/roda.stl"/>
      </geometry>
      <material name="roda_material">
        <color rgba="0.301961 0.301961 0.301961 1"/>
      </material>
    </visual>
    <collision>
      <origin xyz="2.2562e-17 0 -0.038" rpy="1.5708 -6.58658e-17 0"/>
      <geometry>
        <mesh filename="file://$(find full_robot)/assets/roda.stl"/>
      </geometry>
    </collision>
  </link>

  <!-- Link rolete -->
  <link name="rolete">
    <inertial>
      <origin xyz="-1.88278e-33 8.82616e-19 -0.0175" rpy="0 0 0"/>
      <mass value="0.00952544"/>
      <inertia ixx="1.03687e-06" ixy="0" ixz="4.88821e-23" iyy="1.03687e-06" iyz="0" izz="4.20254e-07"/>
    </inertial>
    <!-- Part rolete -->
    <visual>
      <origin xyz="0 8.67362e-19 -0.0175" rpy="1.5708 1.5708 0"/>
      <geometry>
        <mesh filename="file://$(find full_robot)/assets/rolete.stl"/>
      </geometry>
      <material name="rolete_material">
        <color rgba="0 0 0 1"/>
      </material>
    </visual>
    <collision>
      <origin xyz="0 8.67362e-19 -0.0175" rpy="1.5708 1.5708 0"/>
      <geometry>
        <mesh filename="file://$(find full_robot)/assets/rolete.stl"/>
      </geometry>
    </collision>
  </link>
  <!-- Joint from roda to rolete -->
  <joint name="w1_external_1_passive" type="revolute">
    <origin xyz="0.0175 -0.05 -0.047" rpy="-3.14159 -1.5708 0"/>
    <parent link="roda"/>
    <child link="rolete"/>
    <axis xyz="0 0 1"/>
    <limit effort="10" velocity="10" lower="-3.141592653589793" upper="3.141592653589793"/>
  </joint>
  <!-- Link rolete_2 -->
  <link name="rolete_2">
    <inertial>
      <origin xyz="2.42861e-17 1.52538e-20 -0.0175" rpy="0 0 0"/>
      <mass value="0.00952544"/>
      <inertia ixx="1.03687e-06" ixy="-9.85217e-23" ixz="4.55279e-23" iyy="1.03687e-06" iyz="1.27078e-23" izz="4.20254e-07"/>
    </inertial>
    <!-- Part rolete_2 -->
    <visual>
      <origin xyz="2.42861e-17 0 -0.0175" rpy="1.5708 1.5708 0"/>
      <geometry>
        <mesh filename="file://$(find full_robot)/assets/rolete.stl"/>
      </geometry>
      <material name="rolete_2_material">
        <color rgba="0 0 0 1"/>
      </material>
    </visual>
    <collision>
      <origin xyz="2.42861e-17 0 -0.0175" rpy="1.5708 1.5708 0"/>
      <geometry>
        <mesh filename="file://$(find full_robot)/assets/rolete.stl"/>
      </geometry>
    </collision>
  </link>
  <!-- Joint from roda to rolete_2 -->
  <joint name="w1_external_2_passive" type="revolute">
    <origin xyz="0.0520513 -0.00984456 -0.047" rpy="1.5708 4.16334e-17 2.61799"/>
    <parent link="roda"/>
    <child link="rolete_2"/>
    <axis xyz="0 0 1"/>
    <limit effort="10" velocity="10" lower="-3.141592653589793" upper="3.141592653589793"/>
  </joint>
  <!-- Link rolete_3 -->
  <link name="rolete_3">
    <inertial>
      <origin xyz="-5.55112e-17 1.52538e-20 -0.0175" rpy="0 0 0"/>
      <mass value="0.00952544"/>
      <inertia ixx="1.03687e-06" ixy="-1.13465e-22" ixz="-4.91065e-23" iyy="1.03687e-06" iyz="-4.74348e-23" izz="4.20254e-07"/>
    </inertial>
    <!-- Part rolete_3 -->
    <visual>
      <origin xyz="-5.55112e-17 0 -0.0175" rpy="1.5708 1.5708 0"/>
      <geometry>
        <mesh filename="file://$(find full_robot)/assets/rolete.stl"/>
      </geometry>
      <material name="rolete_3_material">
        <color rgba="0 0 0 1"/>
      </material>
    </visual>
    <collision>
      <origin xyz="-5.55112e-17 0 -0.0175" rpy="1.5708 1.5708 0"/>
      <geometry>
        <mesh filename="file://$(find full_robot)/assets/rolete.stl"/>
      </geometry>
    </collision>
  </link>
  <!-- Joint from roda to rolete_3 -->
  <joint name="w1_external_3_passive" type="revolute">
    <origin xyz="0.0520513 0.00984456 -0.047" rpy="-1.5708 4.16334e-17 -2.61799"/>
    <parent link="roda"/>
    <child link="rolete_3"/>
    <axis xyz="0 0 1"/>
    <limit effort="10" velocity="10" lower="-3.141592653589793" upper="3.141592653589793"/>
  </joint>
  <!-- Link rolete_4 -->
  <link name="rolete_4">
    <inertial>
      <origin xyz="-1.88278e-33 1.52538e-20 -0.0175" rpy="0 0 0"/>
      <mass value="0.00952544"/>
      <inertia ixx="1.03687e-06" ixy="0" ixz="4.88821e-23" iyy="1.03687e-06" iyz="0" izz="4.20254e-07"/>
    </inertial>
    <!-- Part rolete_4 -->
    <visual>
      <origin xyz="0 0 -0.0175" rpy="1.5708 1.5708 0"/>
      <geometry>
        <mesh filename="file://$(find full_robot)/assets/rolete.stl"/>
      </geometry>
      <material name="rolete_4_material">
        <color rgba="0 0 0 1"/>
      </material>
    </visual>
    <collision>
      <origin xyz="0 0 -0.0175" rpy="1.5708 1.5708 0"/>
      <geometry>
        <mesh filename="file://$(find full_robot)/assets/rolete.stl"/>
      </geometry>
    </collision>
  </link>
  <!-- Joint from roda to rolete_4 -->
  <joint name="w1_external_4_passive" type="revolute">
    <origin xyz="0.0175 0.05 -0.047" rpy="-3.14159 -1.5708 0"/>
    <parent link="roda"/>
    <child link="rolete_4"/>
    <axis xyz="0 0 1"/>
    <limit effort="10" velocity="10" lower="-3.141592653589793" upper="3.141592653589793"/>
  </joint>
  <!-- Link rolete_5 -->
  <link name="rolete_5">
    <inertial>
      <origin xyz="2.77556e-17 -5.54959e-17 -0.0175" rpy="0 0 0"/>
      <mass value="0.00952544"/>
      <inertia ixx="1.03687e-06" ixy="-4.09638e-23" ixz="-1.08183e-23" iyy="1.03687e-06" iyz="-6.5886e-23" izz="4.20254e-07"/>
    </inertial>
    <!-- Part rolete_5 -->
    <visual>
      <origin xyz="2.77556e-17 -5.55112e-17 -0.0175" rpy="1.5708 1.5708 0"/>
      <geometry>
        <mesh filename="file://$(find full_robot)/assets/rolete.stl"/>
      </geometry>
      <material name="rolete_5_material">
        <color rgba="0 0 0 1"/>
      </material>
    </visual>
    <collision>
      <origin xyz="2.77556e-17 -5.55112e-17 -0.0175" rpy="1.5708 1.5708 0"/>
      <geometry>
        <mesh filename="file://$(find full_robot)/assets/rolete.stl"/>
      </geometry>
    </collision>
  </link>
  <!-- Joint from roda to rolete_5 -->
  <joint name="w1_external_5_passive" type="revolute">
    <origin xyz="-0.0345513 0.0401554 -0.047" rpy="1.5708 9.71445e-17 2.61799"/>
    <parent link="roda"/>
    <child link="rolete_5"/>
    <axis xyz="0 0 1"/>
    <limit effort="10" velocity="10" lower="-3.141592653589793" upper="3.141592653589793"/>
  </joint>
  <!-- Link rolete_6 -->
  <link name="rolete_6">
    <inertial>
      <origin xyz="-1.04083e-17 1.52538e-20 -0.0175" rpy="0 0 0"/>
      <mass value="0.00952544"/>
      <inertia ixx="1.03687e-06" ixy="-2.76823e-25" ixz="5.07067e-23" iyy="1.03687e-06" iyz="6.9839e-24" izz="4.20254e-07"/>
    </inertial>
    <!-- Part rolete_6 -->
    <visual>
      <origin xyz="-1.04083e-17 0 -0.0175" rpy="1.5708 1.5708 0"/>
      <geometry>
        <mesh filename="file://$(find full_robot)/assets/rolete.stl"/>
      </geometry>
      <material name="rolete_6_material">
        <color rgba="0 0 0 1"/>
      </material>
    </visual>
    <collision>
      <origin xyz="-1.04083e-17 0 -0.0175" rpy="1.5708 1.5708 0"/>
      <geometry>
        <mesh filename="file://$(find full_robot)/assets/rolete.stl"/>
      </geometry>
    </collision>
  </link>
  <!-- Joint from roda to rolete_6 -->
  <joint name="w1_external_6_passive" type="revolute">
    <origin xyz="-0.0345513 -0.0401554 -0.047" rpy="-1.5708 4.16334e-17 -2.61799"/>
    <parent link="roda"/>
    <child link="rolete_6"/>
    <axis xyz="0 0 1"/>
    <limit effort="10" velocity="10" lower="-3.141592653589793" upper="3.141592653589793"/>
  </joint>
  <!-- Link rolete_7 -->
  <link name="rolete_7">
    <inertial>
      <origin xyz="-2.77556e-17 6.95415e-18 -0.0175" rpy="0 0 0"/>
      <mass value="0.00952544"/>
      <inertia ixx="1.03687e-06" ixy="-9.19819e-23" ixz="-7.59568e-23" iyy="1.03687e-06" iyz="-3.2944e-23" izz="4.20254e-07"/>
    </inertial>
    <!-- Part rolete_7 -->
    <visual>
      <origin xyz="-2.77556e-17 6.93889e-18 -0.0175" rpy="1.5708 1.5708 0"/>
      <geometry>
        <mesh filename="file://$(find full_robot)/assets/rolete.stl"/>
      </geometry>
      <material name="rolete_7_material">
        <color rgba="0 0 0 1"/>
      </material>
    </visual>
    <collision>
      <origin xyz="-2.77556e-17 6.93889e-18 -0.0175" rpy="1.5708 1.5708 0"/>
      <geometry>
        <mesh filename="file://$(find full_robot)/assets/rolete.stl"/>
      </geometry>
    </collision>
  </link>
  <!-- Joint from roda to rolete_7 -->
  <joint name="w1_internal_1_passive" type="revolute">
    <origin xyz="0.00984456 -0.0520513 -0.029" rpy="0.523599 -1.5708 0"/>
    <parent link="roda"/>
    <child link="rolete_7"/>
    <axis xyz="0 0 1"/>
    <limit effort="10" velocity="10" lower="-3.141592653589793" upper="3.141592653589793"/>
  </joint>
  <!-- Link rolete_8 -->
  <link name="rolete_8">
    <inertial>
      <origin xyz="-1.38778e-17 -2.77403e-17 -0.0175" rpy="0 0 0"/>
      <mass value="0.00952544"/>
      <inertia ixx="1.03687e-06" ixy="-1.53672e-22" ixz="0" iyy="1.03687e-06" iyz="0" izz="4.20254e-07"/>
    </inertial>
    <!-- Part rolete_8 -->
    <visual>
      <origin xyz="-1.38778e-17 -2.77556e-17 -0.0175" rpy="1.5708 1.5708 0"/>
      <geometry>
        <mesh filename="file://$(find full_robot)/assets/rolete.stl"/>
      </geometry>
      <material name="rolete_8_material">
        <color rgba="0 0 0 1"/>
      </material>
    </visual>
    <collision>
      <origin xyz="-1.38778e-17 -2.77556e-17 -0.0175" rpy="1.5708 1.5708 0"/>
      <geometry>
        <mesh filename="file://$(find full_robot)/assets/rolete.stl"/>
      </geometry>
    </collision>
  </link>
  <!-- Joint from roda to rolete_8 -->
  <joint name="w1_internal_2_passive" type="revolute">
    <origin xyz="0.05 -0.0175 -0.029" rpy="-1.5708 1.03547e-17 3.14159"/>
    <parent link="roda"/>
    <child link="rolete_8"/>
    <axis xyz="0 0 1"/>
    <limit effort="10" velocity="10" lower="-3.141592653589793" upper="3.141592653589793"/>
  </joint>
  <!-- Link rolete_9 -->
  <link name="rolete_9">
    <inertial>
      <origin xyz="6.82635e-34 1.52538e-20 -0.0175" rpy="0 0 0"/>
      <mass value="0.00952544"/>
      <inertia ixx="1.03687e-06" ixy="6.3203e-23" ixz="5.2628e-23" iyy="1.03687e-06" iyz="5.92132e-23" izz="4.20254e-07"/>
    </inertial>
    <!-- Part rolete_9 -->
    <visual>
      <origin xyz="0 0 -0.0175" rpy="1.5708 1.5708 0"/>
      <geometry>
        <mesh filename="file://$(find full_robot)/assets/rolete.stl"/>
      </geometry>
      <material name="rolete_9_material">
        <color rgba="0 0 0 1"/>
      </material>
    </visual>
    <collision>
      <origin xyz="0 0 -0.0175" rpy="1.5708 1.5708 0"/>
      <geometry>
        <mesh filename="file://$(find full_robot)/assets/rolete.stl"/>
      </geometry>
    </collision>
  </link>
  <!-- Joint from roda to rolete_9 -->
  <joint name="w1_internal_3_passive" type="revolute">
    <origin xyz="0.00984456 0.0520513 -0.029" rpy="-0.523599 -1.5708 0"/>
    <parent link="roda"/>
    <child link="rolete_9"/>
    <axis xyz="0 0 1"/>
    <limit effort="10" velocity="10" lower="-3.141592653589793" upper="3.141592653589793"/>
  </joint>
  <!-- Link rolete_10 -->
  <link name="rolete_10">
    <inertial>
      <origin xyz="-2.77556e-17 -1.38625e-17 -0.0175" rpy="0 0 0"/>
      <mass value="0.00952544"/>
      <inertia ixx="1.03687e-06" ixy="-7.79102e-24" ixz="2.82681e-23" iyy="1.03687e-06" iyz="-8.65482e-23" izz="4.20254e-07"/>
    </inertial>
    <!-- Part rolete_10 -->
    <visual>
      <origin xyz="-2.77556e-17 -1.38778e-17 -0.0175" rpy="1.5708 1.5708 0"/>
      <geometry>
        <mesh filename="file://$(find full_robot)/assets/rolete.stl"/>
      </geometry>
      <material name="rolete_10_material">
        <color rgba="0 0 0 1"/>
      </material>
    </visual>
    <collision>
      <origin xyz="-2.77556e-17 -1.38778e-17 -0.0175" rpy="1.5708 1.5708 0"/>
      <geometry>
        <mesh filename="file://$(find full_robot)/assets/rolete.stl"/>
      </geometry>
    </collision>
  </link>
  <!-- Joint from roda to rolete_10 -->
  <joint name="w1_internal_4_passive" type="revolute">
    <origin xyz="-0.00984456 0.0520513 -0.029" rpy="-2.61799 -1.5708 0"/>
    <parent link="roda"/>
    <child link="rolete_10"/>
    <axis xyz="0 0 1"/>
    <limit effort="10" velocity="10" lower="-3.141592653589793" upper="3.141592653589793"/>
  </joint>
  <!-- Link rolete_11 -->
  <link name="rolete_11">
    <inertial>
      <origin xyz="2.02133e-36 -1.52538e-20 -0.0175" rpy="0 0 0"/>
      <mass value="0.00952544"/>
      <inertia ixx="1.03687e-06" ixy="-1.53672e-22" ixz="-7.14611e-54" iyy="1.03687e-06" iyz="4.14841e-38" izz="4.20254e-07"/>
    </inertial>
    <!-- Part rolete_11 -->
    <visual>
      <origin xyz="0 0 -0.0175" rpy="-1.5708 -1.5708 0"/>
      <geometry>
        <mesh filename="file://$(find full_robot)/assets/rolete.stl"/>
      </geometry>
      <material name="rolete_11_material">
        <color rgba="0 0 0 1"/>
      </material>
    </visual>
    <collision>
      <origin xyz="0 0 -0.0175" rpy="-1.5708 -1.5708 0"/>
      <geometry>
        <mesh filename="file://$(find full_robot)/assets/rolete.stl"/>
      </geometry>
    </collision>
  </link>
  <!-- Joint from roda to rolete_11 -->
  <joint name="w1_internal_5_passive" type="revolute">
    <origin xyz="-0.05 -0.0175 -0.029" rpy="-1.5708 6.58658e-17 -3.14159"/>
    <parent link="roda"/>
    <child link="rolete_11"/>
    <axis xyz="0 0 1"/>
    <limit effort="10" velocity="10" lower="-3.141592653589793" upper="3.141592653589793"/>
  </joint>
  <!-- Link rolete_12 -->
  <link name="rolete_12">
    <inertial>
      <origin xyz="2.77556e-17 6.92364e-18 -0.0175" rpy="0 0 0"/>
      <mass value="0.00952544"/>
      <inertia ixx="1.03687e-06" ixy="-6.3203e-23" ixz="-5.2628e-23" iyy="1.03687e-06" iyz="5.92132e-23" izz="4.20254e-07"/>
    </inertial>
    <!-- Part rolete_12 -->
    <visual>
      <origin xyz="2.77556e-17 6.93889e-18 -0.0175" rpy="-1.5708 -1.5708 0"/>
      <geometry>
        <mesh filename="file://$(find full_robot)/assets/rolete.stl"/>
      </geometry>
      <material name="rolete_12_material">
        <color rgba="0 0 0 1"/>
      </material>
    </visual>
    <collision>
      <origin xyz="2.77556e-17 6.93889e-18 -0.0175" rpy="-1.5708 -1.5708 0"/>
      <geometry>
        <mesh filename="file://$(find full_robot)/assets/rolete.stl"/>
      </geometry>
    </collision>
  </link>
  <!-- Joint from roda to rolete_12 -->
  <joint name="w1_internal_6_passive" type="revolute">
    <origin xyz="-0.00984456 -0.0520513 -0.029" rpy="2.61799 -1.5708 0"/>
    <parent link="roda"/>
    <child link="rolete_12"/>
    <axis xyz="0 0 1"/>
    <limit effort="10" velocity="10" lower="-3.141592653589793" upper="3.141592653589793"/>
  </joint>
  <!-- Joint from base to roda -->
  <joint name="wheel1_speed" type="revolute">
    <origin xyz="-0.183056 -0.105688 -0.04535" rpy="-1.5708 -0 -1.0472"/>
    <parent link="base"/>
    <child link="roda"/>
    <axis xyz="0 0 1"/>
    <limit effort="10" velocity="10" lower="-3.141592653589793" upper="3.141592653589793"/>
  </joint>
  <!-- Link roda_2 -->
  <link name="roda_2">
    <inertial>
      <origin xyz="2.17054e-17 -5.10809e-18 -0.0362488" rpy="0 0 0"/>
      <mass value="0.174179"/>
      <inertia ixx="0.000112667" ixy="0" ixz="-3.25532e-21" iyy="0.000112667" iyz="0" izz="0.000186298"/>
    </inertial>
    <!-- Part roda_2 -->
    <visual>
      <origin xyz="1.92401e-17 0 -0.038" rpy="1.5708 1.08886e-17 0"/>
      <geometry>
        <mesh filename="file://$(find full_robot)/assets/roda.stl"/>
      </geometry>
      <material name="roda_2_material">
        <color rgba="0 0 0 1"/>
      </material>
    </visual>
    <collision>
      <origin xyz="1.92401e-17 0 -0.038" rpy="1.5708 1.08886e-17 0"/>
      <geometry>
        <mesh filename="file://$(find full_robot)/assets/roda.stl"/>
      </geometry>
    </collision>
  </link>
  <!-- Link rolete_13 -->
  <link name="rolete_13">
    <inertial>
      <origin xyz="-6.33141e-34 -1.52538e-20 -0.0175" rpy="0 0 0"/>
      <mass value="0.00952544"/>
      <inertia ixx="1.03687e-06" ixy="0" ixz="-1.58661e-23" iyy="1.03687e-06" iyz="0" izz="4.20254e-07"/>
    </inertial>
    <!-- Part rolete_13 -->
    <visual>
      <origin xyz="0 0 -0.0175" rpy="-1.5708 -1.5708 0"/>
      <geometry>
        <mesh filename="file://$(find full_robot)/assets/rolete.stl"/>
      </geometry>
      <material name="rolete_13_material">
        <color rgba="0 0 0 1"/>
      </material>
    </visual>
    <collision>
      <origin xyz="0 0 -0.0175" rpy="-1.5708 -1.5708 0"/>
      <geometry>
        <mesh filename="file://$(find full_robot)/assets/rolete.stl"/>
      </geometry>
    </collision>
  </link>
  <!-- Joint from roda_2 to rolete_13 -->
  <joint name="w2_external_1_passive" type="revolute">
    <origin xyz="0.0175 -0.05 -0.047" rpy="-3.14159 -1.5708 0"/>
    <parent link="roda_2"/>
    <child link="rolete_13"/>
    <axis xyz="0 0 1"/>
    <limit effort="10" velocity="10" lower="-3.141592653589793" upper="3.141592653589793"/>
  </joint>
  <!-- Link rolete_14 -->
  <link name="rolete_14">
    <inertial>
      <origin xyz="5.89806e-17 5.54959e-17 -0.0175" rpy="0 0 0"/>
      <mass value="0.00952544"/>
      <inertia ixx="1.03687e-06" ixy="1.58284e-22" ixz="-5.80014e-23" iyy="1.03687e-06" iyz="-5.34805e-23" izz="4.20254e-07"/>
    </inertial>
    <!-- Part rolete_14 -->
    <visual>
      <origin xyz="5.89806e-17 5.55112e-17 -0.0175" rpy="-1.5708 -1.5708 0"/>
      <geometry>
        <mesh filename="file://$(find full_robot)/assets/rolete.stl"/>
      </geometry>
      <material name="rolete_14_material">
        <color rgba="0 0 0 1"/>
      </material>
    </visual>
    <collision>
      <origin xyz="5.89806e-17 5.55112e-17 -0.0175" rpy="-1.5708 -1.5708 0"/>
      <geometry>
        <mesh filename="file://$(find full_robot)/assets/rolete.stl"/>
      </geometry>
    </collision>
  </link>
  <!-- Joint from roda_2 to rolete_14 -->
  <joint name="w2_external_2_passive" type="revolute">
    <origin xyz="0.0520513 -0.00984456 -0.047" rpy="-1.5708 8.32667e-17 -0.523599"/>
    <parent link="roda_2"/>
    <child link="rolete_14"/>
    <axis xyz="0 0 1"/>
    <limit effort="10" velocity="10" lower="-3.141592653589793" upper="3.141592653589793"/>
  </joint>
  <!-- Link rolete_15 -->
  <link name="rolete_15">
    <inertial>
      <origin xyz="-6.22407e-33 -5.55264e-17 -0.0175" rpy="0 0 0"/>
      <mass value="0.00952544"/>
      <inertia ixx="1.03687e-06" ixy="-1.07921e-23" ixz="-3.67177e-23" iyy="1.03687e-06" iyz="-6.53609e-23" izz="4.20254e-07"/>
    </inertial>
    <!-- Part rolete_15 -->
    <visual>
      <origin xyz="0 -5.55112e-17 -0.0175" rpy="-1.5708 -1.5708 0"/>
      <geometry>
        <mesh filename="file://$(find full_robot)/assets/rolete.stl"/>
      </geometry>
      <material name="rolete_15_material">
        <color rgba="0 0 0 1"/>
      </material>
    </visual>
    <collision>
      <origin xyz="0 -5.55112e-17 -0.0175" rpy="-1.5708 -1.5708 0"/>
      <geometry>
        <mesh filename="file://$(find full_robot)/assets/rolete.stl"/>
      </geometry>
    </collision>
  </link>
  <!-- Joint from roda_2 to rolete_15 -->
  <joint name="w2_external_3_passive" type="revolute">
    <origin xyz="0.0345513 0.0401554 -0.047" rpy="-1.5708 -1.94289e-16 0.523599"/>
    <parent link="roda_2"/>
    <child link="rolete_15"/>
    <axis xyz="0 0 1"/>
    <limit effort="10" velocity="10" lower="-3.141592653589793" upper="3.141592653589793"/>
  </joint>
  <!-- Link rolete_16 -->
  <link name="rolete_16">
    <inertial>
      <origin xyz="-6.33141e-34 -1.52538e-20 -0.0175" rpy="0 0 0"/>
      <mass value="0.00952544"/>
      <inertia ixx="1.03687e-06" ixy="0" ixz="-1.58661e-23" iyy="1.03687e-06" iyz="0" izz="4.20254e-07"/>
    </inertial>
    <!-- Part rolete_16 -->
    <visual>
      <origin xyz="0 0 -0.0175" rpy="-1.5708 -1.5708 0"/>
      <geometry>
        <mesh filename="file://$(find full_robot)/assets/rolete.stl"/>
      </geometry>
      <material name="rolete_16_material">
        <color rgba="0 0 0 1"/>
      </material>
    </visual>
    <collision>
      <origin xyz="0 0 -0.0175" rpy="-1.5708 -1.5708 0"/>
      <geometry>
        <mesh filename="file://$(find full_robot)/assets/rolete.stl"/>
      </geometry>
    </collision>
  </link>
  <!-- Joint from roda_2 to rolete_16 -->
  <joint name="w2_external_4_passive" type="revolute">
    <origin xyz="0.0175 0.05 -0.047" rpy="-3.14159 -1.5708 0"/>
    <parent link="roda_2"/>
    <child link="rolete_16"/>
    <axis xyz="0 0 1"/>
    <limit effort="10" velocity="10" lower="-3.141592653589793" upper="3.141592653589793"/>
  </joint>
  <!-- Link rolete_17 -->
  <link name="rolete_17">
    <inertial>
      <origin xyz="-7.95469e-33 -1.52538e-20 -0.0175" rpy="0 0 0"/>
      <mass value="0.00952544"/>
      <inertia ixx="1.03687e-06" ixy="1.00726e-22" ixz="-9.96199e-23" iyy="1.03687e-06" iyz="4.07741e-24" izz="4.20254e-07"/>
    </inertial>
    <!-- Part rolete_17 -->
    <visual>
      <origin xyz="0 0 -0.0175" rpy="-1.5708 -1.5708 0"/>
      <geometry>
        <mesh filename="file://$(find full_robot)/assets/rolete.stl"/>
      </geometry>
      <material name="rolete_17_material">
        <color rgba="0 0 0 1"/>
      </material>
    </visual>
    <collision>
      <origin xyz="0 0 -0.0175" rpy="-1.5708 -1.5708 0"/>
      <geometry>
        <mesh filename="file://$(find full_robot)/assets/rolete.stl"/>
      </geometry>
    </collision>
  </link>
  <!-- Joint from roda_2 to rolete_17 -->
  <joint name="w2_external_5_passive" type="revolute">
    <origin xyz="-0.0345513 0.0401554 -0.047" rpy="-1.5708 2.77556e-17 -0.523599"/>
    <parent link="roda_2"/>
    <child link="rolete_17"/>
    <axis xyz="0 0 1"/>
    <limit effort="10" velocity="10" lower="-3.141592653589793" upper="3.141592653589793"/>
  </joint>
  <!-- Link rolete_18 -->
  <link name="rolete_18">
    <inertial>
      <origin xyz="-1.73472e-17 -1.52538e-20 -0.0175" rpy="0 0 0"/>
      <mass value="0.00952544"/>
      <inertia ixx="1.03687e-06" ixy="-8.15865e-24" ixz="4.60549e-24" iyy="1.03687e-06" iyz="2.75667e-24" izz="4.20254e-07"/>
    </inertial>
    <!-- Part rolete_18 -->
    <visual>
      <origin xyz="-1.73472e-17 0 -0.0175" rpy="-1.5708 -1.5708 0"/>
      <geometry>
        <mesh filename="file://$(find full_robot)/assets/rolete.stl"/>
      </geometry>
      <material name="rolete_18_material">
        <color rgba="0 0 0 1"/>
      </material>
    </visual>
    <collision>
      <origin xyz="-1.73472e-17 0 -0.0175" rpy="-1.5708 -1.5708 0"/>
      <geometry>
        <mesh filename="file://$(find full_robot)/assets/rolete.stl"/>
      </geometry>
    </collision>
  </link>
  <!-- Joint from roda_2 to rolete_18 -->
  <joint name="w2_external_6_passive" type="revolute">
    <origin xyz="-0.0520513 -0.00984456 -0.047" rpy="-1.5708 -2.498e-16 0.523599"/>
    <parent link="roda_2"/>
    <child link="rolete_18"/>
    <axis xyz="0 0 1"/>
    <limit effort="10" velocity="10" lower="-3.141592653589793" upper="3.141592653589793"/>
  </joint>
  <!-- Link rolete_19 -->
  <link name="rolete_19">
    <inertial>
      <origin xyz="-2.42071e-33 1.74998e-18 -0.0175" rpy="0 0 0"/>
      <mass value="0.00952544"/>
      <inertia ixx="1.03687e-06" ixy="-1.74888e-23" ixz="-2.56718e-23" iyy="1.03687e-06" iyz="-9.61519e-24" izz="4.20254e-07"/>
    </inertial>
    <!-- Part rolete_19 -->
    <visual>
      <origin xyz="0 1.73472e-18 -0.0175" rpy="1.5708 1.5708 0"/>
      <geometry>
        <mesh filename="file://$(find full_robot)/assets/rolete.stl"/>
      </geometry>
      <material name="rolete_19_material">
        <color rgba="0 0 0 1"/>
      </material>
    </visual>
    <collision>
      <origin xyz="0 1.73472e-18 -0.0175" rpy="1.5708 1.5708 0"/>
      <geometry>
        <mesh filename="file://$(find full_robot)/assets/rolete.stl"/>
      </geometry>
    </collision>
  </link>
  <!-- Joint from roda_2 to rolete_19 -->
  <joint name="w2_internal_1_passive" type="revolute">
    <origin xyz="0.00984456 -0.0520513 -0.029" rpy="0.523599 -1.5708 0"/>
    <parent link="roda_2"/>
    <child link="rolete_19"/>
    <axis xyz="0 0 1"/>
    <limit effort="10" velocity="10" lower="-3.141592653589793" upper="3.141592653589793"/>
  </joint>
  <!-- Link rolete_20 -->
  <link name="rolete_20">
    <inertial>
      <origin xyz="1.38778e-17 2.77708e-17 -0.0175" rpy="0 0 0"/>
      <mass value="0.00952544"/>
      <inertia ixx="1.03687e-06" ixy="2.25803e-23" ixz="0" iyy="1.03687e-06" iyz="0" izz="4.20254e-07"/>
    </inertial>
    <!-- Part rolete_20 -->
    <visual>
      <origin xyz="1.38778e-17 2.77556e-17 -0.0175" rpy="1.5708 1.5708 0"/>
      <geometry>
        <mesh filename="file://$(find full_robot)/assets/rolete.stl"/>
      </geometry>
      <material name="rolete_20_material">
        <color rgba="0 0 0 1"/>
      </material>
    </visual>
    <collision>
      <origin xyz="1.38778e-17 2.77556e-17 -0.0175" rpy="1.5708 1.5708 0"/>
      <geometry>
        <mesh filename="file://$(find full_robot)/assets/rolete.stl"/>
      </geometry>
    </collision>
  </link>
  <!-- Joint from roda_2 to rolete_20 -->
  <joint name="w2_internal_2_passive" type="revolute">
    <origin xyz="0.05 0.0175 -0.029" rpy="-1.5708 1.08886e-17 0"/>
    <parent link="roda_2"/>
    <child link="rolete_20"/>
    <axis xyz="0 0 1"/>
    <limit effort="10" velocity="10" lower="-3.141592653589793" upper="3.141592653589793"/>
  </joint>
  <!-- Link rolete_21 -->
  <link name="rolete_21">
    <inertial>
      <origin xyz="2.77556e-17 1.52538e-20 -0.0175" rpy="0 0 0"/>
      <mass value="0.00952544"/>
      <inertia ixx="1.03687e-06" ixy="1.74888e-23" ixz="-5.52149e-23" iyy="1.03687e-06" iyz="-2.69076e-23" izz="4.20254e-07"/>
    </inertial>
    <!-- Part rolete_21 -->
    <visual>
      <origin xyz="2.77556e-17 0 -0.0175" rpy="1.5708 1.5708 0"/>
      <geometry>
        <mesh filename="file://$(find full_robot)/assets/rolete.stl"/>
      </geometry>
      <material name="rolete_21_material">
        <color rgba="0 0 0 1"/>
      </material>
    </visual>
    <collision>
      <origin xyz="2.77556e-17 0 -0.0175" rpy="1.5708 1.5708 0"/>
      <geometry>
        <mesh filename="file://$(find full_robot)/assets/rolete.stl"/>
      </geometry>
    </collision>
  </link>
  <!-- Joint from roda_2 to rolete_21 -->
  <joint name="w2_internal_3_passive" type="revolute">
    <origin xyz="0.00984456 0.0520513 -0.029" rpy="-0.523599 -1.5708 0"/>
    <parent link="roda_2"/>
    <child link="rolete_21"/>
    <axis xyz="0 0 1"/>
    <limit effort="10" velocity="10" lower="-3.141592653589793" upper="3.141592653589793"/>
  </joint>
  <!-- Link rolete_22 -->
  <link name="rolete_22">
    <inertial>
      <origin xyz="2.77556e-17 1.52538e-20 -0.0175" rpy="0 0 0"/>
      <mass value="0.00952544"/>
      <inertia ixx="1.03687e-06" ixy="-1.74888e-23" ixz="-5.52149e-23" iyy="1.03687e-06" iyz="2.69076e-23" izz="4.20254e-07"/>
    </inertial>
    <!-- Part rolete_22 -->
    <visual>
      <origin xyz="2.77556e-17 0 -0.0175" rpy="1.5708 1.5708 0"/>
      <geometry>
        <mesh filename="file://$(find full_robot)/assets/rolete.stl"/>
      </geometry>
      <material name="rolete_22_material">
        <color rgba="0 0 0 1"/>
      </material>
    </visual>
    <collision>
      <origin xyz="2.77556e-17 0 -0.0175" rpy="1.5708 1.5708 0"/>
      <geometry>
        <mesh filename="file://$(find full_robot)/assets/rolete.stl"/>
      </geometry>
    </collision>
  </link>
  <!-- Joint from roda_2 to rolete_22 -->
  <joint name="w2_internal_4_passive" type="revolute">
    <origin xyz="-0.0401554 0.0345513 -0.029" rpy="0.523599 -1.5708 0"/>
    <parent link="roda_2"/>
    <child link="rolete_22"/>
    <axis xyz="0 0 1"/>
    <limit effort="10" velocity="10" lower="-3.141592653589793" upper="3.141592653589793"/>
  </joint>
  <!-- Link rolete_23 -->
  <link name="rolete_23">
    <inertial>
      <origin xyz="1.38778e-17 2.77708e-17 -0.0175" rpy="0 0 0"/>
      <mass value="0.00952544"/>
      <inertia ixx="1.03687e-06" ixy="2.25803e-23" ixz="0" iyy="1.03687e-06" iyz="0" izz="4.20254e-07"/>
    </inertial>
    <!-- Part rolete_23 -->
    <visual>
      <origin xyz="1.38778e-17 2.77556e-17 -0.0175" rpy="1.5708 1.5708 0"/>
      <geometry>
        <mesh filename="file://$(find full_robot)/assets/rolete.stl"/>
      </geometry>
      <material name="rolete_23_material">
        <color rgba="0 0 0 1"/>
      </material>
    </visual>
    <collision>
      <origin xyz="1.38778e-17 2.77556e-17 -0.0175" rpy="1.5708 1.5708 0"/>
      <geometry>
        <mesh filename="file://$(find full_robot)/assets/rolete.stl"/>
      </geometry>
    </collision>
  </link>
  <!-- Joint from roda_2 to rolete_23 -->
  <joint name="w2_internal_5_passive" type="revolute">
    <origin xyz="-0.05 0.0175 -0.029" rpy="-1.5708 1.08886e-17 0"/>
    <parent link="roda_2"/>
    <child link="rolete_23"/>
    <axis xyz="0 0 1"/>
    <limit effort="10" velocity="10" lower="-3.141592653589793" upper="3.141592653589793"/>
  </joint>
  <!-- Link rolete_24 -->
  <link name="rolete_24">
    <inertial>
      <origin xyz="-5.55112e-17 -5.18892e-18 -0.0175" rpy="0 0 0"/>
      <mass value="0.00952544"/>
      <inertia ixx="1.03687e-06" ixy="6.50295e-23" ixz="2.11543e-23" iyy="1.03687e-06" iyz="-4.04997e-23" izz="4.20254e-07"/>
    </inertial>
    <!-- Part rolete_24 -->
    <visual>
      <origin xyz="-5.55112e-17 -5.20417e-18 -0.0175" rpy="1.5708 1.5708 0"/>
      <geometry>
        <mesh filename="file://$(find full_robot)/assets/rolete.stl"/>
      </geometry>
      <material name="rolete_24_material">
        <color rgba="0 0 0 1"/>
      </material>
    </visual>
    <collision>
      <origin xyz="-5.55112e-17 -5.20417e-18 -0.0175" rpy="1.5708 1.5708 0"/>
      <geometry>
        <mesh filename="file://$(find full_robot)/assets/rolete.stl"/>
      </geometry>
    </collision>
  </link>
  <!-- Joint from roda_2 to rolete_24 -->
  <joint name="w2_internal_6_passive" type="revolute">
    <origin xyz="-0.0401554 -0.0345513 -0.029" rpy="-0.523599 -1.5708 0"/>
    <parent link="roda_2"/>
    <child link="rolete_24"/>
    <axis xyz="0 0 1"/>
    <limit effort="10" velocity="10" lower="-3.141592653589793" upper="3.141592653589793"/>
  </joint>
  <!-- Joint from base to roda_2 -->
  <joint name="wheel2_speed" type="revolute">
    <origin xyz="0.183056 -0.105688 -0.04535" rpy="-1.5708 -0 1.0472"/>
    <parent link="base"/>
    <child link="roda_2"/>
    <axis xyz="0 0 1"/>
    <limit effort="10" velocity="10" lower="-3.141592653589793" upper="3.141592653589793"/>
  </joint>
  <!-- Link roda_3 -->
  <link name="roda_3">
    <inertial>
      <origin xyz="1.37601e-17 -5.10809e-18 -0.0362488" rpy="0 0 0"/>
      <mass value="0.174179"/>
      <inertia ixx="0.000112667" ixy="0" ixz="0" iyy="0.000112667" iyz="0" izz="0.000186298"/>
    </inertial>
    <!-- Part roda_3 -->
    <visual>
      <origin xyz="1.12757e-17 0 -0.038" rpy="1.5708 -0 0"/>
      <geometry>
        <mesh filename="file://$(find full_robot)/assets/roda.stl"/>
      </geometry>
      <material name="roda_3_material">
        <color rgba="0 0 0 1"/>
      </material>
    </visual>
    <collision>
      <origin xyz="1.12757e-17 0 -0.038" rpy="1.5708 -0 0"/>
      <geometry>
        <mesh filename="file://$(find full_robot)/assets/roda.stl"/>
      </geometry>
    </collision>
  </link>
  <!-- Link rolete_25 -->
  <link name="rolete_25">
    <inertial>
      <origin xyz="1.46499e-50 1.52538e-20 -0.0175" rpy="0 0 0"/>
      <mass value="0.00952544"/>
      <inertia ixx="1.03687e-06" ixy="0" ixz="0" iyy="1.03687e-06" iyz="0" izz="4.20254e-07"/>
    </inertial>
    <!-- Part rolete_25 -->
    <visual>
      <origin xyz="0 0 -0.0175" rpy="1.5708 1.5708 0"/>
      <geometry>
        <mesh filename="file://$(find full_robot)/assets/rolete.stl"/>
      </geometry>
      <material name="rolete_25_material">
        <color rgba="0 0 0 1"/>
      </material>
    </visual>
    <collision>
      <origin xyz="0 0 -0.0175" rpy="1.5708 1.5708 0"/>
      <geometry>
        <mesh filename="file://$(find full_robot)/assets/rolete.stl"/>
      </geometry>
    </collision>
  </link>
  <!-- Joint from roda_3 to rolete_25 -->
  <joint name="w3_external_1_passive" type="revolute">
    <origin xyz="0.0175 0.05 -0.047" rpy="-0 1.5708 0"/>
    <parent link="roda_3"/>
    <child link="rolete_25"/>
    <axis xyz="0 0 1"/>
    <limit effort="10" velocity="10" lower="-3.141592653589793" upper="3.141592653589793"/>
  </joint>
  <!-- Link rolete_26 -->
  <link name="rolete_26">
    <inertial>
      <origin xyz="1.46499e-50 -3.45419e-18 -0.0175" rpy="0 0 0"/>
      <mass value="0.00952544"/>
      <inertia ixx="1.03687e-06" ixy="0" ixz="0" iyy="1.03687e-06" iyz="2.33288e-23" izz="4.20254e-07"/>
    </inertial>
    <!-- Part rolete_26 -->
    <visual>
      <origin xyz="0 -3.46945e-18 -0.0175" rpy="1.5708 1.5708 0"/>
      <geometry>
        <mesh filename="file://$(find full_robot)/assets/rolete.stl"/>
      </geometry>
      <material name="rolete_26_material">
        <color rgba="0 0 0 1"/>
      </material>
    </visual>
    <collision>
      <origin xyz="0 -3.46945e-18 -0.0175" rpy="1.5708 1.5708 0"/>
      <geometry>
        <mesh filename="file://$(find full_robot)/assets/rolete.stl"/>
      </geometry>
    </collision>
  </link>
  <!-- Joint from roda_3 to rolete_26 -->
  <joint name="w3_external_2_passive" type="revolute">
    <origin xyz="-0.0520513 0.00984456 -0.047" rpy="2.0944 1.5708 0"/>
    <parent link="roda_3"/>
    <child link="rolete_26"/>
    <axis xyz="0 0 1"/>
    <limit effort="10" velocity="10" lower="-3.141592653589793" upper="3.141592653589793"/>
  </joint>
  <!-- Link rolete_27 -->
  <link name="rolete_27">
    <inertial>
      <origin xyz="7.3099e-49 1.52538e-20 -0.0175" rpy="0 0 0"/>
      <mass value="0.00952544"/>
      <inertia ixx="1.03687e-06" ixy="-5.11217e-38" ixz="-5.18004e-39" iyy="1.03687e-06" iyz="-4.0886e-24" izz="4.20254e-07"/>
    </inertial>
    <!-- Part rolete_27 -->
    <visual>
      <origin xyz="0 0 -0.0175" rpy="1.5708 1.5708 0"/>
      <geometry>
        <mesh filename="file://$(find full_robot)/assets/rolete.stl"/>
      </geometry>
      <material name="rolete_27_material">
        <color rgba="0 0 0 1"/>
      </material>
    </visual>
    <collision>
      <origin xyz="0 0 -0.0175" rpy="1.5708 1.5708 0"/>
      <geometry>
        <mesh filename="file://$(find full_robot)/assets/rolete.stl"/>
      </geometry>
    </collision>
  </link>
  <!-- Joint from roda_3 to rolete_27 -->
  <joint name="w3_external_3_passive" type="revolute">
    <origin xyz="-0.0345513 -0.0401554 -0.047" rpy="1.0472 1.5708 0"/>
    <parent link="roda_3"/>
    <child link="rolete_27"/>
    <axis xyz="0 0 1"/>
    <limit effort="10" velocity="10" lower="-3.141592653589793" upper="3.141592653589793"/>
  </joint>
  <!-- Link rolete_28 -->
  <link name="rolete_28">
    <inertial>
      <origin xyz="1.46499e-50 1.52538e-20 -0.0175" rpy="0 0 0"/>
      <mass value="0.00952544"/>
      <inertia ixx="1.03687e-06" ixy="0" ixz="0" iyy="1.03687e-06" iyz="0" izz="4.20254e-07"/>
    </inertial>
    <!-- Part rolete_28 -->
    <visual>
      <origin xyz="0 0 -0.0175" rpy="1.5708 1.5708 0"/>
      <geometry>
        <mesh filename="file://$(find full_robot)/assets/rolete.stl"/>
      </geometry>
      <material name="rolete_28_material">
        <color rgba="0 0 0 1"/>
      </material>
    </visual>
    <collision>
      <origin xyz="0 0 -0.0175" rpy="1.5708 1.5708 0"/>
      <geometry>
        <mesh filename="file://$(find full_robot)/assets/rolete.stl"/>
      </geometry>
    </collision>
  </link>
  <!-- Joint from roda_3 to rolete_28 -->
  <joint name="w3_external_4_passive" type="revolute">
    <origin xyz="0.0175 -0.05 -0.047" rpy="-0 1.5708 0"/>
    <parent link="roda_3"/>
    <child link="rolete_28"/>
    <axis xyz="0 0 1"/>
    <limit effort="10" velocity="10" lower="-3.141592653589793" upper="3.141592653589793"/>
  </joint>
  <!-- Link rolete_29 -->
  <link name="rolete_29">
    <inertial>
      <origin xyz="-8.14659e-50 1.52538e-20 -0.0175" rpy="0 0 0"/>
      <mass value="0.00952544"/>
      <inertia ixx="1.03687e-06" ixy="-2.55609e-38" ixz="-2.65791e-38" iyy="1.03687e-06" iyz="-1.58661e-23" izz="4.20254e-07"/>
    </inertial>
    <!-- Part rolete_29 -->
    <visual>
      <origin xyz="0 0 -0.0175" rpy="1.5708 1.5708 0"/>
      <geometry>
        <mesh filename="file://$(find full_robot)/assets/rolete.stl"/>
      </geometry>
      <material name="rolete_29_material">
        <color rgba="0 0 0 1"/>
      </material>
    </visual>
    <collision>
      <origin xyz="0 0 -0.0175" rpy="1.5708 1.5708 0"/>
      <geometry>
        <mesh filename="file://$(find full_robot)/assets/rolete.stl"/>
      </geometry>
    </collision>
  </link>
  <!-- Joint from roda_3 to rolete_29 -->
  <joint name="w3_external_5_passive" type="revolute">
    <origin xyz="0.0345513 -0.0401554 -0.047" rpy="2.0944 1.5708 0"/>
    <parent link="roda_3"/>
    <child link="rolete_29"/>
    <axis xyz="0 0 1"/>
    <limit effort="10" velocity="10" lower="-3.141592653589793" upper="3.141592653589793"/>
  </joint>
  <!-- Link rolete_30 -->
  <link name="rolete_30">
    <inertial>
      <origin xyz="1.46499e-50 -6.92364e-18 -0.0175" rpy="0 0 0"/>
      <mass value="0.00952544"/>
      <inertia ixx="1.03687e-06" ixy="0" ixz="0" iyy="1.03687e-06" iyz="5.80741e-24" izz="4.20254e-07"/>
    </inertial>
    <!-- Part rolete_30 -->
    <visual>
      <origin xyz="0 -6.93889e-18 -0.0175" rpy="1.5708 1.5708 0"/>
      <geometry>
        <mesh filename="file://$(find full_robot)/assets/rolete.stl"/>
      </geometry>
      <material name="rolete_30_material">
        <color rgba="0 0 0 1"/>
      </material>
    </visual>
    <collision>
      <origin xyz="0 -6.93889e-18 -0.0175" rpy="1.5708 1.5708 0"/>
      <geometry>
        <mesh filename="file://$(find full_robot)/assets/rolete.stl"/>
      </geometry>
    </collision>
  </link>
  <!-- Joint from roda_3 to rolete_30 -->
  <joint name="w3_external_6_passive" type="revolute">
    <origin xyz="0.0520513 0.00984456 -0.047" rpy="1.0472 1.5708 0"/>
    <parent link="roda_3"/>
    <child link="rolete_30"/>
    <axis xyz="0 0 1"/>
    <limit effort="10" velocity="10" lower="-3.141592653589793" upper="3.141592653589793"/>
  </joint>
  <!-- Link rolete_31 -->
  <link name="rolete_31">
    <inertial>
      <origin xyz="-1.06334e-48 -1.74998e-18 -0.0175" rpy="0 0 0"/>
      <mass value="0.00952544"/>
      <inertia ixx="1.03687e-06" ixy="1.71225e-39" ixz="-2.05193e-38" iyy="1.03687e-06" iyz="-3.65425e-23" izz="4.20254e-07"/>
    </inertial>
    <!-- Part rolete_31 -->
    <visual>
      <origin xyz="0 -1.73472e-18 -0.0175" rpy="-1.5708 -1.5708 0"/>
      <geometry>
        <mesh filename="file://$(find full_robot)/assets/rolete.stl"/>
      </geometry>
      <material name="rolete_31_material">
        <color rgba="0 0 0 1"/>
      </material>
    </visual>
    <collision>
      <origin xyz="0 -1.73472e-18 -0.0175" rpy="-1.5708 -1.5708 0"/>
      <geometry>
        <mesh filename="file://$(find full_robot)/assets/rolete.stl"/>
      </geometry>
    </collision>
  </link>
  <!-- Joint from roda_3 to rolete_31 -->
  <joint name="w3_internal_1_passive" type="revolute">
    <origin xyz="-0.0401554 0.0345513 -0.029" rpy="2.61799 1.5708 0"/>
    <parent link="roda_3"/>
    <child link="rolete_31"/>
    <axis xyz="0 0 1"/>
    <limit effort="10" velocity="10" lower="-3.141592653589793" upper="3.141592653589793"/>
  </joint>
  <!-- Link rolete_32 -->
  <link name="rolete_32">
    <inertial>
      <origin xyz="1.46499e-50 -1.52538e-20 -0.0175" rpy="0 0 0"/>
      <mass value="0.00952544"/>
      <inertia ixx="1.03687e-06" ixy="0" ixz="0" iyy="1.03687e-06" iyz="0" izz="4.20254e-07"/>
    </inertial>
    <!-- Part rolete_32 -->
    <visual>
      <origin xyz="0 0 -0.0175" rpy="-1.5708 -1.5708 0"/>
      <geometry>
        <mesh filename="file://$(find full_robot)/assets/rolete.stl"/>
      </geometry>
      <material name="rolete_32_material">
        <color rgba="0 0 0 1"/>
      </material>
    </visual>
    <collision>
      <origin xyz="0 0 -0.0175" rpy="-1.5708 -1.5708 0"/>
      <geometry>
        <mesh filename="file://$(find full_robot)/assets/rolete.stl"/>
      </geometry>
    </collision>
  </link>
  <!-- Joint from roda_3 to rolete_32 -->
  <joint name="w3_internal_2_passive" type="revolute">
    <origin xyz="-0.05 -0.0175 -0.029" rpy="1.5708 1.5708 0"/>
    <parent link="roda_3"/>
    <child link="rolete_32"/>
    <axis xyz="0 0 1"/>
    <limit effort="10" velocity="10" lower="-3.141592653589793" upper="3.141592653589793"/>
  </joint>
  <!-- Link rolete_33 -->
  <link name="rolete_33">
    <inertial>
      <origin xyz="-7.05248e-49 1.38625e-17 -0.0175" rpy="0 0 0"/>
      <mass value="0.00952544"/>
      <inertia ixx="1.03687e-06" ixy="1.52775e-38" ixz="-8.56768e-39" iyy="1.03687e-06" iyz="9.6008e-24" izz="4.20254e-07"/>
    </inertial>
    <!-- Part rolete_33 -->
    <visual>
      <origin xyz="0 1.38778e-17 -0.0175" rpy="-1.5708 -1.5708 0"/>
      <geometry>
        <mesh filename="file://$(find full_robot)/assets/rolete.stl"/>
      </geometry>
      <material name="rolete_33_material">
        <color rgba="0 0 0 1"/>
      </material>
    </visual>
    <collision>
      <origin xyz="0 1.38778e-17 -0.0175" rpy="-1.5708 -1.5708 0"/>
      <geometry>
        <mesh filename="file://$(find full_robot)/assets/rolete.stl"/>
      </geometry>
    </collision>
  </link>
  <!-- Joint from roda_3 to rolete_33 -->
  <joint name="w3_internal_3_passive" type="revolute">
    <origin xyz="-0.0401554 -0.0345513 -0.029" rpy="-2.61799 1.5708 0"/>
    <parent link="roda_3"/>
    <child link="rolete_33"/>
    <axis xyz="0 0 1"/>
    <limit effort="10" velocity="10" lower="-3.141592653589793" upper="3.141592653589793"/>
  </joint>
  <!-- Link rolete_34 -->
  <link name="rolete_34">
    <inertial>
      <origin xyz="7.31228e-49 -1.52538e-20 -0.0175" rpy="0 0 0"/>
      <mass value="0.00952544"/>
      <inertia ixx="1.03687e-06" ixy="2.38486e-38" ixz="-1.21018e-39" iyy="1.03687e-06" iyz="5.17505e-23" izz="4.20254e-07"/>
    </inertial>
    <!-- Part rolete_34 -->
    <visual>
      <origin xyz="0 0 -0.0175" rpy="-1.5708 -1.5708 0"/>
      <geometry>
        <mesh filename="file://$(find full_robot)/assets/rolete.stl"/>
      </geometry>
      <material name="rolete_34_material">
        <color rgba="0 0 0 1"/>
      </material>
    </visual>
    <collision>
      <origin xyz="0 0 -0.0175" rpy="-1.5708 -1.5708 0"/>
      <geometry>
        <mesh filename="file://$(find full_robot)/assets/rolete.stl"/>
      </geometry>
    </collision>
  </link>
  <!-- Joint from roda_3 to rolete_34 -->
  <joint name="w3_internal_4_passive" type="revolute">
    <origin xyz="0.00984456 -0.0520513 -0.029" rpy="2.61799 1.5708 0"/>
    <parent link="roda_3"/>
    <child link="rolete_34"/>
    <axis xyz="0 0 1"/>
    <limit effort="10" velocity="10" lower="-3.141592653589793" upper="3.141592653589793"/>
  </joint>
  <!-- Link rolete_35 -->
  <link name="rolete_35">
    <inertial>
      <origin xyz="1.46499e-50 -1.52538e-20 -0.0175" rpy="0 0 0"/>
      <mass value="0.00952544"/>
      <inertia ixx="1.03687e-06" ixy="0" ixz="0" iyy="1.03687e-06" iyz="0" izz="4.20254e-07"/>
    </inertial>
    <!-- Part rolete_35 -->
    <visual>
      <origin xyz="0 0 -0.0175" rpy="-1.5708 -1.5708 0"/>
      <geometry>
        <mesh filename="file://$(find full_robot)/assets/rolete.stl"/>
      </geometry>
      <material name="rolete_35_material">
        <color rgba="0 0 0 1"/>
      </material>
    </visual>
    <collision>
      <origin xyz="0 0 -0.0175" rpy="-1.5708 -1.5708 0"/>
      <geometry>
        <mesh filename="file://$(find full_robot)/assets/rolete.stl"/>
      </geometry>
    </collision>
  </link>
  <!-- Joint from roda_3 to rolete_35 -->
  <joint name="w3_internal_5_passive" type="revolute">
    <origin xyz="0.05 -0.0175 -0.029" rpy="1.5708 -0 0"/>
    <parent link="roda_3"/>
    <child link="rolete_35"/>
    <axis xyz="0 0 1"/>
    <limit effort="10" velocity="10" lower="-3.141592653589793" upper="3.141592653589793"/>
  </joint>
  <!-- Link rolete_36 -->
  <link name="rolete_36">
    <inertial>
      <origin xyz="-2.77556e-17 -1.74998e-18 -0.0175" rpy="0 0 0"/>
      <mass value="0.00952544"/>
      <inertia ixx="1.03687e-06" ixy="1.71225e-39" ixz="2.62122e-39" iyy="1.03687e-06" iyz="3.65425e-23" izz="4.20254e-07"/>
    </inertial>
    <!-- Part rolete_36 -->
    <visual>
      <origin xyz="-2.77556e-17 -1.73472e-18 -0.0175" rpy="-1.5708 -1.5708 0"/>
      <geometry>
        <mesh filename="file://$(find full_robot)/assets/rolete.stl"/>
      </geometry>
      <material name="rolete_36_material">
        <color rgba="0 0 0 1"/>
      </material>
    </visual>
    <collision>
      <origin xyz="-2.77556e-17 -1.73472e-18 -0.0175" rpy="-1.5708 -1.5708 0"/>
      <geometry>
        <mesh filename="file://$(find full_robot)/assets/rolete.stl"/>
      </geometry>
    </collision>
  </link>
  <!-- Joint from roda_3 to rolete_36 -->
  <joint name="w3_internal_6_passive" type="revolute">
    <origin xyz="0.00984456 0.0520513 -0.029" rpy="-2.61799 1.5708 0"/>
    <parent link="roda_3"/>
    <child link="rolete_36"/>
    <axis xyz="0 0 1"/>
    <limit effort="10" velocity="10" lower="-3.141592653589793" upper="3.141592653589793"/>
  </joint>
  <!-- Joint from base to roda_3 -->
  <joint name="wheel3_speed" type="revolute">
    <origin xyz="-1.18552e-17 0.211375 -0.04535" rpy="1.5708 -0 2.10573e-16"/>
    <parent link="base"/>
    <child link="roda_3"/>
    <axis xyz="0 0 1"/>
    <limit effort="10" velocity="10" lower="-3.141592653589793" upper="3.141592653589793"/>
  </joint>
</robot>
