<?xml version="1.0" ?>
<!-- =================================================================================== -->
<!-- |    This document was autogenerated by xacro from manipulator.xacro              | -->
<!-- |    EDITING THIS FILE BY HAND IS NOT RECOMMENDED                                 | -->
<!-- =================================================================================== -->
<!-- Generated using onshape-to-robot -->
<!-- Onshape https://cad.onshape.com/documents/8ad4b3e8e68952b2f8c65a07/w/3c1f775842712cbb585088e7/e/2e75ac6943677df920499bc9 -->
<robot name="manipulator">
  <ros2_control name="GazeboSystem" type="system">
    <hardware>
      <plugin>gazebo_ros2_control/GazeboSystem</plugin>
    </hardware>
    <joint name="link1_to_link2">
      <command_interface name="position"/>
      <state_interface name="position"/>
      <state_interface name="velocity"/>
    </joint>
    <joint name="link2_to_ee">
      <command_interface name="position"/>
      <state_interface name="position"/>
      <state_interface name="velocity"/>
    </joint>
  </ros2_control>
  <gazebo>
    <plugin filename="libgazebo_ros2_control.so" name="gazebo_ros2_control">
      <ros>
        <argument>--ros-args</argument>
        <argument>--params-file</argument>
        <argument>/home/thiago/Documents/FEI/graduacao/TCC/software/install/omnicare_manipulator/share/omnicare_manipulator/config/manipulator_controller.yaml</argument>
      </ros>
      <parameters>/home/thiago/Documents/FEI/graduacao/TCC/software/install/omnicare_manipulator/share/omnicare_manipulator/config/manipulator_controller.yaml</parameters>
    </plugin>
  </gazebo>
  <link name="world"/>
  <joint name="world_to_base" type="fixed">
    <origin rpy="0 0 0" xyz="0 0 0"/>
    <parent link="world"/>
    <child link="base_link"/>
  </joint>
  <link name="base_link"/>
  <joint name="base_link_to_link_1" type="fixed">
    <origin rpy="0 0 0" xyz="0 0 0"/>
    <parent link="base_link"/>
    <child link="link_1_manip"/>
  </joint>
  <!-- Link link_1_manip -->
  <link name="link_1_manip">
    <inertial>
      <origin rpy="0 0 0" xyz="0 0 0"/>
      <mass value="10"/>
      <inertia ixx="10" ixy="0" ixz="0" iyy="10" iyz="0" izz="10"/>
    </inertial>
    <!-- Part link_1_manip -->
    <visual>
      <origin rpy="0 -0 0" xyz="0 0 0"/>
      <geometry>
        <mesh filename="file:///home/thiago/Documents/FEI/graduacao/TCC/software/install/omnicare_manipulator/share/omnicare_manipulator/meshes/link_1_manip.stl"/>
      </geometry>
      <material name="link_1_manip_material">
        <color rgba="0.647059 0.647059 0.647059 1"/>
      </material>
    </visual>
    <collision>
      <origin rpy="0 -0 0" xyz="0 0 0"/>
      <geometry>
        <mesh filename="file:///home/thiago/Documents/FEI/graduacao/TCC/software/install/omnicare_manipulator/share/omnicare_manipulator/meshes/link_1_manip.stl"/>
      </geometry>
    </collision>
  </link>
  <!-- Link link_2_manip -->
  <link name="link_2_manip">
    <inertial>
      <origin rpy="0 0 0" xyz="0 0 0"/>
      <mass value="0.001"/>
      <inertia ixx="1" ixy="0" ixz="0" iyy="1" iyz="0" izz="1"/>
    </inertial>
    <!-- Part link_2_manip -->
    <visual>
      <origin rpy="0 -0 0" xyz="-0.322023 -0.0908839 -0.358902"/>
      <geometry>
        <mesh filename="file:///home/thiago/Documents/FEI/graduacao/TCC/software/install/omnicare_manipulator/share/omnicare_manipulator/meshes/link_2_manip.stl"/>
      </geometry>
      <material name="link_2_manip_material">
        <color rgba="0.615686 0.811765 0.929412 1"/>
      </material>
    </visual>
    <collision>
      <origin rpy="0 -0 0" xyz="-0.322023 -0.0908839 -0.358902"/>
      <geometry>
        <mesh filename="file:///home/thiago/Documents/FEI/graduacao/TCC/software/install/omnicare_manipulator/share/omnicare_manipulator/meshes/link_2_manip.stl"/>
      </geometry>
    </collision>
  </link>
  <!-- Link end_effector -->
  <link name="end_effector">
    <inertial>
      <origin rpy="0 0 0" xyz="0 0 0"/>
      <mass value="0.001"/>
      <inertia ixx="0.5" ixy="0" ixz="0" iyy="0.5" iyz="0" izz="0.5"/>
    </inertial>
    <!-- Part end_effector -->
    <visual>
      <origin rpy="-1.5708 -1.5708 0" xyz="-0.246085 -0.514643 0.0549023"/>
      <geometry>
        <mesh filename="file:///home/thiago/Documents/FEI/graduacao/TCC/software/install/omnicare_manipulator/share/omnicare_manipulator/meshes/end_effector.stl"/>
      </geometry>
      <material name="end_effector_material">
        <color rgba="0.231373 0.380392 0.705882 1"/>
      </material>
    </visual>
    <collision>
      <origin rpy="-1.5708 -1.5708 0" xyz="-0.246085 -0.514643 0.0549023"/>
      <geometry>
        <mesh filename="file:///home/thiago/Documents/FEI/graduacao/TCC/software/install/omnicare_manipulator/share/omnicare_manipulator/meshes/end_effector.stl"/>
      </geometry>
    </collision>
  </link>
  <!-- Joint from link_2_manip to end_effector -->
  <joint name="link2_to_ee" type="prismatic">
    <origin rpy="1.5708 0 1.5708" xyz="-0.040 -0.06 0.025"/>
    <parent link="link_2_manip"/>
    <child link="end_effector"/>
    <axis xyz="0 0 1"/>
    <limit effort="1000.0" lower="0" upper="0.15" velocity="1.0"/>
    <dynamics damping="0.0" friction="0.0"/>
  </joint>
  <!-- Joint from link_1_manip to link_2_manip -->
  <joint name="link1_to_link2" type="prismatic">
    <origin rpy="0 0 0" xyz="0 0 0.11625"/>
    <parent link="link_1_manip"/>
    <child link="link_2_manip"/>
    <axis xyz="0 0 1"/>
    <limit effort="1000.0" lower="0.0" upper="0.48" velocity="1.0"/>
    <dynamics damping="0.0" friction="0.0"/>
  </joint>
</robot>
